<robot name="robot" version="1.0">
  <joint name="Cone_link_joint" type="fixed">
    <origin rpy="1.57080 0.00000 0.00000" xyz="0.00000 -0.12479 0.00000"/>
    <parent link="Sphere_link"/>
    <child link="Cone_link"/>
  </joint>
  <joint name="Cone_w2_link_joint" type="fixed">
    <origin rpy="1.57080 0.00000 0.00000" xyz="-0.00000 -0.12479 -0.00000"/>
    <parent link="Sphere_w2_link"/>
    <child link="Cone_w2_link"/>
  </joint>
  <joint name="Cone_w3_link_joint" type="fixed">
    <origin rpy="1.57080 -0.00000 -0.00000" xyz="-0.00000 -0.12479 0.00000"/>
    <parent link="Sphere_w3_link"/>
    <child link="Cone_w3_link"/>
  </joint>
  <joint name="Cone_w4_link_joint" type="fixed">
    <origin rpy="1.57080 -0.00000 -0.00000" xyz="0.00000 -0.12479 -0.00000"/>
    <parent link="Sphere_w4_link"/>
    <child link="Cone_w4_link"/>
  </joint>
  <joint name="Cube_trailer_2_link_joint" type="fixed">
    <origin rpy="0.00000 0.00000 0.00000" xyz="0.35456 0.85200 0.70968"/>
    <parent link="chasis_link"/>
    <child link="Cube_trailer_2_link"/>
  </joint>
  <joint name="Cube_trailer_3_link_joint" type="fixed">
    <origin rpy="0.00000 0.00000 1.57080" xyz="1.57008 -0.09844 0.70917"/>
    <parent link="chasis_link"/>
    <child link="Cube_trailer_3_link"/>
  </joint>
  <joint name="Cube_trailer_4_link_joint" type="fixed">
    <origin rpy="0.00000 0.00000 1.57080" xyz="-0.85539 -0.09844 0.70917"/>
    <parent link="chasis_link"/>
    <child link="Cube_trailer_4_link"/>
  </joint>
  <joint name="Cube_trailer_link_joint" type="fixed">
    <origin rpy="0.00000 0.00000 0.00000" xyz="0.35456 -1.04857 0.70968"/>
    <parent link="chasis_link"/>
    <child link="Cube_trailer_link"/>
  </joint>
  <joint name="Cylinder_link_joint" type="fixed">
    <origin rpy="-0.26180 0.00000 0.00000" xyz="-1.25000 -0.65807 -0.39906"/>
    <parent link="chasis_link"/>
    <child link="Cylinder_link"/>
  </joint>
  <joint name="Cylinder_w2_link_joint" type="fixed">
    <origin rpy="-0.26180 0.00000 0.00000" xyz="1.25000 -0.65807 -0.39860"/>
    <parent link="chasis_link"/>
    <child link="Cylinder_w2_link"/>
  </joint>
  <joint name="Cylinder_w3_link_joint" type="fixed">
    <origin rpy="-0.26180 -0.00000 -3.14159" xyz="-1.25000 0.47479 -0.40695"/>
    <parent link="chasis_link"/>
    <child link="Cylinder_w3_link"/>
  </joint>
  <joint name="Cylinder_w4_link_joint" type="fixed">
    <origin rpy="-0.26180 -0.00000 -3.14159" xyz="1.25000 0.47479 -0.40719"/>
    <parent link="chasis_link"/>
    <child link="Cylinder_w4_link"/>
  </joint>
  <joint name="Sphere_link_joint" type="fixed">
    <origin rpy="0.26180 0.00000 0.00000" xyz="0.00000 -0.01047 -0.41352"/>
    <parent link="Cylinder_link"/>
    <child link="Sphere_link"/>
  </joint>
  <joint name="Sphere_w2_link_joint" type="fixed">
    <origin rpy="0.26180 0.00000 0.00000" xyz="0.00000 -0.01047 -0.41352"/>
    <parent link="Cylinder_w2_link"/>
    <child link="Sphere_w2_link"/>
  </joint>
  <joint name="Sphere_w3_link_joint" type="fixed">
    <origin rpy="0.26180 0.00000 0.00000" xyz="-0.00000 -0.01267 -0.40736"/>
    <parent link="Cylinder_w3_link"/>
    <child link="Sphere_w3_link"/>
  </joint>
  <joint name="Sphere_w4_link_joint" type="fixed">
    <origin rpy="0.26180 0.00000 0.00000" xyz="-0.00000 -0.01267 -0.40736"/>
    <parent link="Cylinder_w4_link"/>
    <child link="Sphere_w4_link"/>
  </joint>
  <joint name="arm_cilynder_1_link_joint" type="revolute">
    <limit lower="-3.14000" upper="3.14000" effort="0.00000" velocity="0.00000"/>
    <origin rpy="0.00000 0.00000 0.00000" xyz="0.00000 0.00000 0.76594"/>
    <parent link="base_arm_cube_link"/>
    <child link="arm_cilynder_1_link"/>
    <axis xyz="0.00000 0.00000 1.00000"/>
  </joint>
  <joint name="arm_cilynder_2_link_joint" type="prismatic">
    <limit lower="-1.20000" upper="1.30000" effort="0.00000" velocity="0.00000"/>
    <origin rpy="0.00000 0.00000 0.00000" xyz="0.00000 -0.00000 1.05000"/>
    <parent link="cylinder_jnt_2_link"/>
    <child link="arm_cilynder_2_link"/>
    <axis xyz="0.00000 0.00000 1.00000"/>
  </joint>
  <joint name="arm_cube_1_link_joint" type="fixed">
    <origin rpy="0.00000 0.00000 0.00000" xyz="-0.60749 0.00000 0.58880"/>
    <parent link="arm_cilynder_1_link"/>
    <child link="arm_cube_1_link"/>
  </joint>
  <joint name="arm_cube_2_link_joint" type="fixed">
    <origin rpy="0.00000 0.00000 1.57080" xyz="-0.01161 -0.70550 0.00000"/>
    <parent link="cylinder_jnt_1_link"/>
    <child link="arm_cube_2_link"/>
  </joint>
  <joint name="back_finger_link_joint" type="prismatic">
    <limit lower="0.06000" upper="0.00000" effort="0.00000" velocity="0.00000"/>
    <origin rpy="0.00000 0.00000 1.57080" xyz="0.32481 -0.00033 -0.24871"/>
    <parent link="hand_cube_link"/>
    <child link="back_finger_link"/>
    <axis xyz="0.00000 1.00000 0.00000"/>
  </joint>
  <joint name="base_arm_cube_link_joint" type="fixed">
    <origin rpy="0.00000 0.00000 0.00000" xyz="-1.25000 -0.10000 0.48960"/>
    <parent link="chasis_link"/>
    <child link="base_arm_cube_link"/>
  </joint>
  <joint name="cylinder_jnt_1_link_joint" type="revolute">
    <limit lower="-4.34000" upper="1.20000" effort="0.00000" velocity="0.00000"/>
    <origin rpy="0.00000 0.00000 0.00000" xyz="-0.68724 0.00000 0.50820"/>
    <parent link="arm_cube_1_link"/>
    <child link="cylinder_jnt_1_link"/>
    <axis xyz="0.00000 0.00000 1.00000"/>
  </joint>
  <joint name="cylinder_jnt_2_link_joint" type="fixed">
    <origin rpy="0.00000 0.00000 -1.57080" xyz="-0.70726 -0.01063 0.00000"/>
    <parent link="arm_cube_2_link"/>
    <child link="cylinder_jnt_2_link"/>
  </joint>
  <joint name="front_finger_link_joint" type="prismatic">
    <limit lower="0.06000" upper="0.00000" effort="0.00000" velocity="0.00000"/>
    <origin rpy="0.00000 0.00000 1.57080" xyz="-0.32415 -0.00033 -0.24741"/>
    <parent link="hand_cube_link"/>
    <child link="front_finger_link"/>
    <axis xyz="0.00000 1.00000 0.00000"/>
  </joint>
  <joint name="hand_cube_link_joint" type="fixed">
    <origin rpy="0.00000 0.00000 0.00000" xyz="0.00000 -0.00000 -0.07303"/>
    <parent link="hand_cylinder_link"/>
    <child link="hand_cube_link"/>
  </joint>
  <joint name="hand_cylinder_link_joint" type="revolute">
    <limit lower="-3.14000" upper="3.14000" effort="0.00000" velocity="0.00000"/>
    <origin rpy="0.00000 0.00000 0.00000" xyz="0.00000 -0.00000 -2.67343"/>
    <parent link="arm_cilynder_2_link"/>
    <child link="hand_cylinder_link"/>
    <axis xyz="0.00000 0.00000 1.00000"/>
  </joint>
  <joint name="left_finger_link_joint" type="prismatic">
    <limit lower="0.06000" upper="0.00000" effort="0.00000" velocity="0.00000"/>
    <origin rpy="0.00000 0.00000 0.00000" xyz="-0.00429 -0.32443 -0.19256"/>
    <parent link="hand_cube_link"/>
    <child link="left_finger_link"/>
    <axis xyz="0.00000 1.00000 0.00000"/>
  </joint>
  <joint name="right_finger_link_joint" type="prismatic">
    <limit lower="0.06000" upper="0.00000" effort="0.00000" velocity="0.00000"/>
    <origin rpy="0.00000 0.00000 0.00000" xyz="-0.00429 0.32378 -0.19256"/>
    <parent link="hand_cube_link"/>
    <child link="right_finger_link"/>
    <axis xyz="0.00000 1.00000 0.00000"/>
  </joint>
  <joint name="wheel_link_joint" type="continuous">
    <limit lower="0" upper="0" effort="0.00000" velocity="0.00000"/>
    <origin rpy="0.00000 0.00000 0.00000" xyz="0.00000 0.00000 0.10000"/>
    <parent link="Cone_link"/>
    <child link="wheel_link"/>
    <axis xyz="0.00000 0.00000 1.00000"/>
  </joint>
  <joint name="wheel_w2_link_joint" type="continuous">
    <limit lower="0" upper="0" effort="0.00000" velocity="0.00000"/>
    <origin rpy="0.00000 0.00000 0.00000" xyz="0.00000 0.00000 0.10000"/>
    <parent link="Cone_w2_link"/>
    <child link="wheel_w2_link"/>
    <axis xyz="0.00000 0.00000 1.00000"/>
  </joint>
  <joint name="wheel_w3_link_joint" type="continuous">
    <limit lower="0" upper="0" effort="0.00000" velocity="0.00000"/>
    <origin rpy="-0.00000 0.00000 -0.00000" xyz="-0.00000 -0.00000 0.10000"/>
    <parent link="Cone_w3_link"/>
    <child link="wheel_w3_link"/>
    <axis xyz="0.00000 0.00000 1.00000"/>
  </joint>
  <joint name="wheel_w4_link_joint" type="continuous">
    <limit lower="0" upper="0" effort="0.00000" velocity="0.00000"/>
    <origin rpy="-0.00000 0.00000 -0.00000" xyz="0.00000 -0.00000 0.10000"/>
    <parent link="Cone_w4_link"/>
    <child link="wheel_w4_link"/>
    <axis xyz="0.00000 0.00000 1.00000"/>
  </joint>
  <link name="Cone_link">
    <collision name="Cone_collision">
      <origin rpy="0.00000 0.00000 0.00000" xyz="0.00000 0.00000 0.00000"/>
      <geometry>
        <mesh filename="../meshes/dae/Cone.001.dae" scale="0.10000 0.10000 0.10000"/>
      </geometry>
    </collision>
    <inertial>
      <inertia ixx="0.00148" ixy="0.00000" ixz="-0.00000" iyy="0.00089" iyz="-0.00000" izz="0.00148"/>
      <origin rpy="0.00000 0.00000 0.00000" xyz="0.00000 -0.00000 -0.05000"/>
      <mass value="0.30000"/>
    </inertial>
    <visual name="Cone">
      <origin rpy="0.00000 0.00000 0.00000" xyz="0.00000 -0.00000 0.00000"/>
      <geometry>
        <mesh filename="../meshes/dae/Cone.001.dae" scale="0.10000 0.10000 0.10000"/>
      </geometry>
    </visual>
  </link>
  <link name="Cone_w2_link">
    <collision name="Cone_w2_collision">
      <origin rpy="0.00000 0.00000 0.00000" xyz="0.00000 -0.00000 -0.00000"/>
      <geometry>
        <mesh filename="../meshes/dae/Cone.002.dae" scale="0.10000 0.10000 0.10000"/>
      </geometry>
    </collision>
    <inertial>
      <inertia ixx="0.00148" ixy="0.00000" ixz="-0.00000" iyy="0.00089" iyz="-0.00000" izz="0.00148"/>
      <origin rpy="0.00000 0.00000 0.00000" xyz="0.00000 -0.00000 -0.05000"/>
      <mass value="0.30000"/>
    </inertial>
    <visual name="Cone_w2">
      <origin rpy="0.00000 0.00000 0.00000" xyz="0.00000 -0.00000 -0.00000"/>
      <geometry>
        <mesh filename="../meshes/dae/Cone.002.dae" scale="0.10000 0.10000 0.10000"/>
      </geometry>
    </visual>
  </link>
  <link name="Cone_w3_link">
    <collision name="Cone_w3_collision">
      <origin rpy="0.00000 0.00000 -3.14159" xyz="0.00000 -0.00000 0.00000"/>
      <geometry>
        <mesh filename="../meshes/dae/Cone.003.dae" scale="0.10000 0.10000 0.10000"/>
      </geometry>
    </collision>
    <inertial>
      <inertia ixx="0.00148" ixy="0.00000" ixz="0.00000" iyy="0.00089" iyz="0.00000" izz="0.00148"/>
      <origin rpy="0.00000 0.00000 0.00000" xyz="0.00000 -0.00000 -0.05000"/>
      <mass value="0.30000"/>
    </inertial>
    <visual name="Cone_w3">
      <origin rpy="-0.00000 0.00000 -0.00000" xyz="0.00000 -0.00000 0.00000"/>
      <geometry>
        <mesh filename="../meshes/dae/Cone.003.dae" scale="0.10000 0.10000 0.10000"/>
      </geometry>
    </visual>
  </link>
  <link name="Cone_w4_link">
    <collision name="Cone_w4_collision">
      <origin rpy="0.00000 0.00000 -3.14159" xyz="0.00000 -0.00000 0.00000"/>
      <geometry>
        <mesh filename="../meshes/dae/Cone.007.dae" scale="0.10000 0.10000 0.10000"/>
      </geometry>
    </collision>
    <inertial>
      <inertia ixx="0.00148" ixy="0.00000" ixz="0.00000" iyy="0.00089" iyz="0.00000" izz="0.00148"/>
      <origin rpy="0.00000 0.00000 0.00000" xyz="0.00000 -0.00000 -0.05000"/>
      <mass value="0.30000"/>
    </inertial>
    <visual name="Cone_w4">
      <origin rpy="-0.00000 0.00000 -0.00000" xyz="0.00000 -0.00000 0.00000"/>
      <geometry>
        <mesh filename="../meshes/dae/Cone.007.dae" scale="0.10000 0.10000 0.10000"/>
      </geometry>
    </visual>
  </link>
  <link name="Cube_trailer_2_link">
    <collision name="Cube_trailer_2_collision">
      <origin rpy="0.00000 0.00000 0.00000" xyz="0.00000 0.00000 0.00000"/>
      <geometry>
        <box size="2.50000 0.10000 0.50000"/>
      </geometry>
    </collision>
    <inertial>
      <inertia ixx="0.65000" ixy="0.00000" ixz="0.00000" iyy="16.25000" iyz="0.00000" izz="15.65000"/>
      <origin rpy="0.00000 0.00000 0.00000" xyz="0.00000 -0.00000 0.00000"/>
      <mass value="30.00000"/>
    </inertial>
    <visual name="Cube_trailer_2">
      <origin rpy="0.00000 0.00000 0.00000" xyz="-0.00000 -0.00000 0.00000"/>
      <geometry>
        <box size="2.50000 0.10000 0.50000"/>
      </geometry>
    </visual>
  </link>
  <link name="Cube_trailer_3_link">
    <collision name="Cube_trailer_3_collision">
      <origin rpy="0.00000 0.00000 0.00000" xyz="-0.00000 -0.00000 0.00000"/>
      <geometry>
        <box size="2.00000 0.10000 0.50000"/>
      </geometry>
    </collision>
    <inertial>
      <inertia ixx="7.08333" ixy="0.00000" ixz="0.00000" iyy="0.43333" iyz="0.00000" izz="6.68333"/>
      <origin rpy="0.00000 0.00000 0.00000" xyz="-0.00000 0.00000 0.00000"/>
      <mass value="20.00000"/>
    </inertial>
    <visual name="Cube_trailer_3">
      <origin rpy="0.00000 0.00000 0.00000" xyz="-0.00000 0.00000 0.00000"/>
      <geometry>
        <box size="2.00000 0.10000 0.50000"/>
      </geometry>
    </visual>
  </link>
  <link name="Cube_trailer_4_link">
    <collision name="Cube_trailer_4_collision">
      <origin rpy="0.00000 0.00000 0.00000" xyz="-0.00000 0.00000 0.00000"/>
      <geometry>
        <box size="2.00000 0.10000 0.50000"/>
      </geometry>
    </collision>
    <inertial>
      <inertia ixx="7.08333" ixy="0.00000" ixz="0.00000" iyy="0.43333" iyz="0.00000" izz="6.68333"/>
      <origin rpy="0.00000 0.00000 0.00000" xyz="0.00000 0.00000 0.00000"/>
      <mass value="20.00000"/>
    </inertial>
    <visual name="Cube_trailer_4">
      <origin rpy="0.00000 0.00000 0.00000" xyz="-0.00000 0.00000 0.00000"/>
      <geometry>
        <box size="2.00000 0.10000 0.50000"/>
      </geometry>
    </visual>
  </link>
  <link name="Cube_trailer_link">
    <collision name="Cube_trailer_collision">
      <origin rpy="0.00000 0.00000 0.00000" xyz="0.00000 0.00000 0.00000"/>
      <geometry>
        <box size="2.50000 0.10000 0.50000"/>
      </geometry>
    </collision>
    <inertial>
      <inertia ixx="0.65000" ixy="0.00000" ixz="0.00000" iyy="16.25000" iyz="0.00000" izz="15.65000"/>
      <origin rpy="0.00000 0.00000 0.00000" xyz="0.00000 0.00000 0.00000"/>
      <mass value="30.00000"/>
    </inertial>
    <visual name="Cube_trailer">
      <origin rpy="0.00000 0.00000 0.00000" xyz="-0.00000 0.00000 0.00000"/>
      <geometry>
        <box size="2.50000 0.10000 0.50000"/>
      </geometry>
    </visual>
  </link>
  <link name="Cylinder_link">
    <collision name="Cylinder_collision">
      <origin rpy="0.00000 0.00000 0.00000" xyz="0.00000 0.00000 0.00000"/>
      <geometry>
        <cylinder radius="0.05000" length="0.75000"/>
      </geometry>
    </collision>
    <inertial>
      <inertia ixx="0.03800" ixy="0.00000" ixz="0.00000" iyy="0.03552" iyz="-0.00925" izz="0.00348"/>
      <origin rpy="0.00000 0.00000 0.00000" xyz="0.00000 0.00000 -0.00000"/>
      <mass value="0.80000"/>
    </inertial>
    <visual name="Cylinder">
      <origin rpy="0.00000 0.00000 0.00000" xyz="0.00000 0.00000 -0.00000"/>
      <geometry>
        <cylinder radius="0.05000" length="0.75000"/>
      </geometry>
    </visual>
  </link>
  <link name="Cylinder_w2_link">
    <collision name="Cylinder_w2_collision">
      <origin rpy="0.00000 0.00000 0.00000" xyz="0.00000 0.00000 -0.00000"/>
      <geometry>
        <cylinder radius="0.05000" length="0.75000"/>
      </geometry>
    </collision>
    <inertial>
      <inertia ixx="0.03800" ixy="0.00000" ixz="0.00000" iyy="0.03552" iyz="-0.00925" izz="0.00348"/>
      <origin rpy="0.00000 0.00000 0.00000" xyz="0.00000 0.00000 -0.00000"/>
      <mass value="0.80000"/>
    </inertial>
    <visual name="Cylinder_w2">
      <origin rpy="0.00000 0.00000 0.00000" xyz="0.00000 0.00000 -0.00000"/>
      <geometry>
        <cylinder radius="0.05000" length="0.75000"/>
      </geometry>
    </visual>
  </link>
  <link name="Cylinder_w3_link">
    <collision name="Cylinder_w3_collision">
      <origin rpy="-0.00000 -0.00000 3.14159" xyz="0.00000 -0.00000 0.00000"/>
      <geometry>
        <cylinder radius="0.05000" length="0.75000"/>
      </geometry>
    </collision>
    <inertial>
      <inertia ixx="0.03800" ixy="0.00000" ixz="-0.00000" iyy="0.03552" iyz="0.00925" izz="0.00348"/>
      <origin rpy="0.00000 0.00000 0.00000" xyz="0.00000 -0.00000 0.00000"/>
      <mass value="0.80000"/>
    </inertial>
    <visual name="Cylinder_w3">
      <origin rpy="0.00000 -0.00000 0.00000" xyz="0.00000 -0.00000 0.00000"/>
      <geometry>
        <cylinder radius="0.05000" length="0.75000"/>
      </geometry>
    </visual>
  </link>
  <link name="Cylinder_w4_link">
    <collision name="Cylinder_w4_collision">
      <origin rpy="-0.00000 -0.00000 3.14159" xyz="-0.00000 0.00000 0.00000"/>
      <geometry>
        <cylinder radius="0.05000" length="0.75000"/>
      </geometry>
    </collision>
    <inertial>
      <inertia ixx="0.03800" ixy="0.00000" ixz="-0.00000" iyy="0.03552" iyz="0.00925" izz="0.00348"/>
      <origin rpy="0.00000 0.00000 0.00000" xyz="-0.00000 0.00000 0.00000"/>
      <mass value="0.80000"/>
    </inertial>
    <visual name="Cylinder_w4">
      <origin rpy="0.00000 -0.00000 0.00000" xyz="-0.00000 -0.00000 0.00000"/>
      <geometry>
        <cylinder radius="0.05000" length="0.75000"/>
      </geometry>
    </visual>
  </link>
  <link name="Sphere_link">
    <collision name="Sphere_collision">
      <origin rpy="0.00000 0.00000 0.00000" xyz="0.00000 0.00000 0.00000"/>
      <geometry>
        <sphere radius="0.10000"/>
      </geometry>
    </collision>
    <inertial>
      <inertia ixx="0.00120" ixy="0.00000" ixz="0.00000" iyy="0.00120" iyz="0.00000" izz="0.00120"/>
      <origin rpy="0.00000 0.00000 0.00000" xyz="0.00000 0.00000 0.00000"/>
      <mass value="0.30000"/>
    </inertial>
    <visual name="Sphere">
      <origin rpy="0.00000 0.00000 0.00000" xyz="0.00000 0.00000 0.00000"/>
      <geometry>
        <sphere radius="0.10000"/>
      </geometry>
    </visual>
  </link>
  <link name="Sphere_w2_link">
    <collision name="Sphere_w2_collision">
      <origin rpy="0.00000 0.00000 0.00000" xyz="-0.00000 -0.00000 -0.00000"/>
      <geometry>
        <sphere radius="0.10000"/>
      </geometry>
    </collision>
    <inertial>
      <inertia ixx="0.00120" ixy="0.00000" ixz="0.00000" iyy="0.00120" iyz="0.00000" izz="0.00120"/>
      <origin rpy="0.00000 0.00000 0.00000" xyz="-0.00000 -0.00000 0.00000"/>
      <mass value="0.30000"/>
    </inertial>
    <visual name="Sphere_w2">
      <origin rpy="0.00000 0.00000 0.00000" xyz="-0.00000 -0.00000 0.00000"/>
      <geometry>
        <sphere radius="0.10000"/>
      </geometry>
    </visual>
  </link>
  <link name="Sphere_w3_link">
    <collision name="Sphere_w3_collision">
      <origin rpy="0.00000 0.00000 3.14159" xyz="0.00000 -0.00000 -0.00000"/>
      <geometry>
        <sphere radius="0.10000"/>
      </geometry>
    </collision>
    <inertial>
      <inertia ixx="0.00120" ixy="0.00000" ixz="0.00000" iyy="0.00120" iyz="-0.00000" izz="0.00120"/>
      <origin rpy="0.00000 0.00000 0.00000" xyz="0.00000 -0.00000 -0.00000"/>
      <mass value="0.30000"/>
    </inertial>
    <visual name="Sphere_w3">
      <origin rpy="0.00000 0.00000 0.00000" xyz="0.00000 -0.00000 -0.00000"/>
      <geometry>
        <sphere radius="0.10000"/>
      </geometry>
    </visual>
  </link>
  <link name="Sphere_w4_link">
    <collision name="Sphere_w4_collision">
      <origin rpy="0.00000 0.00000 3.14159" xyz="0.00000 -0.00000 -0.00000"/>
      <geometry>
        <sphere radius="0.10000"/>
      </geometry>
    </collision>
    <inertial>
      <inertia ixx="0.00120" ixy="0.00000" ixz="0.00000" iyy="0.00120" iyz="-0.00000" izz="0.00120"/>
      <origin rpy="0.00000 0.00000 0.00000" xyz="0.00000 -0.00000 -0.00000"/>
      <mass value="0.30000"/>
    </inertial>
    <visual name="Sphere_w4">
      <origin rpy="0.00000 0.00000 0.00000" xyz="0.00000 -0.00000 -0.00000"/>
      <geometry>
        <sphere radius="0.10000"/>
      </geometry>
    </visual>
  </link>
  <link name="arm_cilynder_1_link">
    <collision name="arm_cilynder_1_collision">
      <origin rpy="0.00000 0.00000 0.00000" xyz="-0.00000 -0.00000 0.22080"/>
      <geometry>
        <cylinder radius="0.07500" length="2.00000"/>
      </geometry>
    </collision>
    <inertial>
      <inertia ixx="0.28336" ixy="0.00000" ixz="0.00000" iyy="0.28336" iyz="0.00000" izz="0.00422"/>
      <origin rpy="0.00000 0.00000 0.00000" xyz="-0.00000 0.00000 0.00000"/>
      <mass value="1.50000"/>
    </inertial>
    <visual name="arm_cilynder_1">
      <origin rpy="0.00000 0.00000 0.00000" xyz="-0.00000 -0.00000 0.22080"/>
      <geometry>
        <cylinder radius="0.07500" length="2.00000"/>
      </geometry>
    </visual>
  </link>
  <link name="arm_cilynder_2_link">
    <collision name="arm_cilynder_2_collision">
      <origin rpy="0.00000 0.00000 0.00000" xyz="0.00000 -0.00000 -1.14646"/>
      <geometry>
        <cylinder radius="0.05000" length="3.00000"/>
      </geometry>
    </collision>
    <inertial>
      <inertia ixx="1.12594" ixy="0.00000" ixz="0.00000" iyy="1.12594" iyz="0.00000" izz="0.00188"/>
      <origin rpy="0.00000 0.00000 0.00000" xyz="0.00000 -0.00000 0.00000"/>
      <mass value="1.50000"/>
    </inertial>
    <visual name="arm_cilynder_2">
      <origin rpy="0.00000 0.00000 0.00000" xyz="-0.00000 -0.00000 -1.14646"/>
      <geometry>
        <cylinder radius="0.05000" length="3.00000"/>
      </geometry>
    </visual>
  </link>
  <link name="arm_cube_1_link">
    <collision name="arm_cube_1_collision">
      <origin rpy="0.00000 0.00000 0.00000" xyz="-0.00000 0.00000 0.50820"/>
      <geometry>
        <box size="1.50000 0.15000 0.15000"/>
      </geometry>
    </collision>
    <inertial>
      <inertia ixx="0.00563" ixy="0.00000" ixz="0.00000" iyy="0.28406" iyz="0.00000" izz="0.28406"/>
      <origin rpy="0.00000 0.00000 0.00000" xyz="-0.00000 0.00000 0.00000"/>
      <mass value="1.50000"/>
    </inertial>
    <visual name="arm_cube_1">
      <origin rpy="0.00000 0.00000 0.00000" xyz="-0.00000 -0.00000 0.50820"/>
      <geometry>
        <box size="1.50000 0.15000 0.15000"/>
      </geometry>
    </visual>
  </link>
  <link name="arm_cube_2_link">
    <collision name="arm_cube_2_collision">
      <origin rpy="0.00000 0.00000 0.00000" xyz="-0.00000 0.00000 0.00000"/>
      <geometry>
        <box size="1.50000 0.15000 0.15000"/>
      </geometry>
    </collision>
    <inertial>
      <inertia ixx="0.28406" ixy="0.00000" ixz="0.00000" iyy="0.00563" iyz="0.00000" izz="0.28406"/>
      <origin rpy="0.00000 0.00000 0.00000" xyz="-0.00000 0.00000 0.00000"/>
      <mass value="1.50000"/>
    </inertial>
    <visual name="arm_cube_2">
      <origin rpy="0.00000 0.00000 0.00000" xyz="-0.00000 0.00000 0.00000"/>
      <geometry>
        <box size="1.50000 0.15000 0.15000"/>
      </geometry>
    </visual>
  </link>
  <link name="back_finger_link">
    <collision name="back_finger_collision">
      <origin rpy="0.00000 0.00000 0.00000" xyz="-0.00000 0.00000 0.00000"/>
      <geometry>
        <box size="0.10000 0.05000 0.40000"/>
      </geometry>
    </collision>
    <inertial>
      <inertia ixx="0.00142" ixy="0.00000" ixz="0.00000" iyy="0.00135" iyz="0.00000" izz="0.00010"/>
      <origin rpy="0.00000 0.00000 0.00000" xyz="-0.00000 0.00000 0.00000"/>
      <mass value="0.10000"/>
    </inertial>
    <visual name="back_finger">
      <origin rpy="0.00000 0.00000 0.00000" xyz="0.00000 0.00000 0.00000"/>
      <geometry>
        <box size="0.10000 0.05000 0.40000"/>
      </geometry>
    </visual>
  </link>
  <link name="base_arm_cube_link">
    <collision name="base_arm_cube_collision">
      <origin rpy="0.00000 0.00000 0.00000" xyz="-0.00000 0.00000 -0.00000"/>
      <geometry>
        <box size="0.50000 0.50000 0.05000"/>
      </geometry>
    </collision>
    <inertial>
      <inertia ixx="0.01052" ixy="0.00000" ixz="0.00000" iyy="0.01052" iyz="0.00000" izz="0.02083"/>
      <origin rpy="0.00000 0.00000 0.00000" xyz="-0.00000 0.00000 -0.00000"/>
      <mass value="0.50000"/>
    </inertial>
    <visual name="base_arm_cube">
      <origin rpy="0.00000 0.00000 0.00000" xyz="-0.00000 0.00000 -0.00000"/>
      <geometry>
        <box size="0.50000 0.50000 0.05000"/>
      </geometry>
    </visual>
  </link>
  <link name="chasis_link">
    <collision name="chasis_collision">
      <origin rpy="0.00000 0.00000 0.00000" xyz="0.00000 -0.09507 0.16631"/>
      <geometry>
        <mesh filename="../meshes/dae/Cube.004.dae" scale="1.62500 1.00000 0.30000"/>
      </geometry>
    </collision>
    <inertial>
      <inertia ixx="109.00000" ixy="0.00000" ixz="0.00000" iyy="273.06250" iyz="0.00000" izz="364.06250"/>
      <origin rpy="0.00000 0.00000 0.00000" xyz="0.00000 -0.10089 0.16631"/>
      <mass value="300.00000"/>
    </inertial>
    <visual name="chasis">
      <origin rpy="0.00000 0.00000 0.00000" xyz="0.00000 -0.10089 0.16631"/>
      <geometry>
        <box size="3.25000 2.00000 0.60000"/>
      </geometry>
    </visual>
  </link>
  <link name="cylinder_jnt_1_link">
    <collision name="cylinder_jnt_1_collision">
      <origin rpy="0.00000 0.00000 0.00000" xyz="-0.00000 -0.00000 0.00000"/>
      <geometry>
        <cylinder radius="0.10000" length="0.30000"/>
      </geometry>
    </collision>
    <inertial>
      <inertia ixx="0.00250" ixy="0.00000" ixz="0.00000" iyy="0.00250" iyz="0.00000" izz="0.00125"/>
      <origin rpy="0.00000 0.00000 0.00000" xyz="-0.00000 -0.00000 0.00000"/>
      <mass value="0.25000"/>
    </inertial>
    <visual name="cylinder_jnt_1">
      <origin rpy="0.00000 0.00000 0.00000" xyz="-0.00000 -0.00000 0.00000"/>
      <geometry>
        <cylinder radius="0.10000" length="0.30000"/>
      </geometry>
    </visual>
  </link>
  <link name="cylinder_jnt_2_link">
    <collision name="cylinder_jnt_2_collision">
      <origin rpy="0.00000 0.00000 0.00000" xyz="0.00000 -0.00000 0.00000"/>
      <geometry>
        <cylinder radius="0.10000" length="0.30000"/>
      </geometry>
    </collision>
    <inertial>
      <inertia ixx="0.00250" ixy="0.00000" ixz="0.00000" iyy="0.00250" iyz="0.00000" izz="0.00125"/>
      <origin rpy="0.00000 0.00000 0.00000" xyz="-0.00000 -0.00000 0.00000"/>
      <mass value="0.25000"/>
    </inertial>
    <visual name="cylinder_jnt_2">
      <origin rpy="0.00000 0.00000 0.00000" xyz="-0.00000 -0.00000 0.00000"/>
      <geometry>
        <cylinder radius="0.10000" length="0.30000"/>
      </geometry>
    </visual>
  </link>
  <link name="front_finger_link">
    <collision name="front_finger_collision">
      <origin rpy="0.00000 0.00000 0.00000" xyz="-0.00000 0.00000 0.00000"/>
      <geometry>
        <box size="0.10000 0.05000 0.40000"/>
      </geometry>
    </collision>
    <inertial>
      <inertia ixx="0.00142" ixy="0.00000" ixz="0.00000" iyy="0.00135" iyz="0.00000" izz="0.00010"/>
      <origin rpy="0.00000 0.00000 0.00000" xyz="-0.00000 0.00000 0.00000"/>
      <mass value="0.10000"/>
    </inertial>
    <visual name="front_finger">
      <origin rpy="0.00000 0.00000 0.00000" xyz="-0.00000 0.00000 0.00000"/>
      <geometry>
        <box size="0.10000 0.05000 0.40000"/>
      </geometry>
    </visual>
  </link>
  <link name="hand_cube_link">
    <collision name="hand_cube_collision">
      <origin rpy="0.00000 0.00000 0.00000" xyz="0.00000 -0.00000 0.00000"/>
      <geometry>
        <box size="0.70000 0.70000 0.10000"/>
      </geometry>
    </collision>
    <inertial>
      <inertia ixx="0.01042" ixy="0.00000" ixz="0.00000" iyy="0.00151" iyz="0.00000" izz="0.01151"/>
      <origin rpy="0.00000 0.00000 0.00000" xyz="-0.00000 -0.00000 0.00000"/>
      <mass value="0.25000"/>
    </inertial>
    <visual name="hand_cube">
      <origin rpy="0.00000 0.00000 0.00000" xyz="-0.00000 -0.00000 0.00000"/>
      <geometry>
        <box size="0.70000 0.70000 0.10000"/>
      </geometry>
    </visual>
  </link>
  <link name="hand_cylinder_link">
    <collision name="hand_cylinder_collision">
      <origin rpy="0.00000 0.00000 0.00000" xyz="0.00000 -0.00000 0.00000"/>
      <geometry>
        <cylinder radius="0.10000" length="0.10000"/>
      </geometry>
    </collision>
    <inertial>
      <inertia ixx="0.00033" ixy="0.00000" ixz="0.00000" iyy="0.00033" iyz="0.00000" izz="0.00050"/>
      <origin rpy="0.00000 0.00000 0.00000" xyz="-0.00000 -0.00000 0.00000"/>
      <mass value="0.10000"/>
    </inertial>
    <visual name="hand_cylinder">
      <origin rpy="0.00000 0.00000 0.00000" xyz="-0.00000 -0.00000 0.00000"/>
      <geometry>
        <cylinder radius="0.10000" length="0.10000"/>
      </geometry>
    </visual>
  </link>
  <link name="left_finger_link">
    <collision name="left_finger_collision">
      <origin rpy="0.00000 0.00000 0.00000" xyz="-0.00000 -0.00000 -0.05744"/>
      <geometry>
        <box size="0.10000 0.05000 0.40000"/>
      </geometry>
    </collision>
    <inertial>
      <inertia ixx="0.00077" ixy="0.00000" ixz="0.00000" iyy="0.00083" iyz="0.00000" izz="0.00010"/>
      <origin rpy="0.00000 0.00000 0.00000" xyz="0.00000 -0.00000 0.00000"/>
      <mass value="0.10000"/>
    </inertial>
    <visual name="left_finger">
      <origin rpy="0.00000 0.00000 0.00000" xyz="-0.00000 -0.00000 -0.05744"/>
      <geometry>
        <box size="0.10000 0.05000 0.40000"/>
      </geometry>
    </visual>
  </link>
  <link name="right_finger_link">
    <collision name="right_finger_collision">
      <origin rpy="0.00000 0.00000 0.00000" xyz="-0.00000 -0.00000 -0.05744"/>
      <geometry>
        <box size="0.10000 0.05000 0.40000"/>
      </geometry>
    </collision>
    <inertial>
      <inertia ixx="0.00077" ixy="0.00000" ixz="0.00000" iyy="0.00083" iyz="0.00000" izz="0.00010"/>
      <origin rpy="0.00000 0.00000 0.00000" xyz="0.00000 -0.00000 0.00000"/>
      <mass value="0.10000"/>
    </inertial>
    <visual name="right_finger">
      <origin rpy="0.00000 0.00000 0.00000" xyz="-0.00000 -0.00000 -0.05744"/>
      <geometry>
        <box size="0.10000 0.05000 0.40000"/>
      </geometry>
    </visual>
  </link>
  <link name="wheel_link">
    <collision name="wheel_collision">
      <origin rpy="0.00000 0.00000 0.00000" xyz="0.00000 0.00000 0.00000"/>
      <geometry>
        <mesh filename="../meshes/dae/Torus.dae" scale="0.20000 0.20000 0.50000"/>
      </geometry>
    </collision>
    <inertial>
      <inertia ixx="0.01774" ixy="0.00000" ixz="0.00000" iyy="0.02932" iyz="0.00000" izz="0.01774"/>
      <origin rpy="0.00000 0.00000 0.00000" xyz="0.00000 -0.00000 -0.00000"/>
      <mass value="1.00000"/>
    </inertial>
    <visual name="wheel">
      <origin rpy="0.00000 0.00000 0.00000" xyz="0.00000 0.00000 0.00000"/>
      <geometry>
        <mesh filename="../meshes/dae/Torus.dae" scale="0.20000 0.20000 0.50000"/>
      </geometry>
    </visual>
  </link>
  <link name="wheel_w2_link">
    <collision name="wheel_w2_collision">
      <origin rpy="0.00000 0.00000 0.00000" xyz="-0.00000 -0.00000 0.00000"/>
      <geometry>
        <mesh filename="../meshes/dae/Torus.001.dae" scale="0.20000 0.20000 0.50000"/>
      </geometry>
    </collision>
    <inertial>
      <inertia ixx="0.01774" ixy="0.00000" ixz="0.00000" iyy="0.02932" iyz="0.00000" izz="0.01774"/>
      <origin rpy="0.00000 0.00000 0.00000" xyz="-0.00000 -0.00000 0.00000"/>
      <mass value="1.00000"/>
    </inertial>
    <visual name="wheel_w2">
      <origin rpy="0.00000 0.00000 0.00000" xyz="-0.00000 -0.00000 0.00000"/>
      <geometry>
        <mesh filename="../meshes/dae/Torus.001.dae" scale="0.20000 0.20000 0.50000"/>
      </geometry>
    </visual>
  </link>
  <link name="wheel_w3_link">
    <collision name="wheel_w3_collision">
      <origin rpy="-3.14159 0.00000 -3.14159" xyz="0.00000 -0.00000 0.00000"/>
      <geometry>
        <mesh filename="../meshes/dae/Torus.002.dae" scale="0.20000 0.20000 0.50000"/>
      </geometry>
    </collision>
    <inertial>
      <inertia ixx="0.01774" ixy="-0.00000" ixz="-0.00000" iyy="0.02932" iyz="-0.00000" izz="0.01774"/>
      <origin rpy="0.00000 0.00000 0.00000" xyz="0.00000 -0.00000 0.00000"/>
      <mass value="1.00000"/>
    </inertial>
    <visual name="wheel_w3">
      <origin rpy="-0.00000 -0.00000 0.00000" xyz="0.00000 -0.00000 0.00000"/>
      <geometry>
        <mesh filename="../meshes/dae/Torus.002.dae" scale="0.20000 0.20000 0.50000"/>
      </geometry>
    </visual>
  </link>
  <link name="wheel_w4_link">
    <collision name="wheel_w4_collision">
      <origin rpy="-3.14159 0.00000 -3.14159" xyz="-0.00000 -0.00000 0.00000"/>
      <geometry>
        <mesh filename="../meshes/dae/Torus.006.dae" scale="0.20000 0.20000 0.50000"/>
      </geometry>
    </collision>
    <inertial>
      <inertia ixx="0.01774" ixy="-0.00000" ixz="-0.00000" iyy="0.02932" iyz="-0.00000" izz="0.01774"/>
      <origin rpy="0.00000 0.00000 0.00000" xyz="0.00000 -0.00000 0.00000"/>
      <mass value="1.00000"/>
    </inertial>
    <visual name="wheel_w4">
      <origin rpy="-0.00000 -0.00000 0.00000" xyz="0.00000 -0.00000 0.00000"/>
      <geometry>
        <mesh filename="../meshes/dae/Torus.006.dae" scale="0.20000 0.20000 0.50000"/>
      </geometry>
    </visual>
  </link>
</robot>