<robot name="robot" version="1.0">
  <joint name="Cone_link_joint" type="fixed">
    <origin rpy="1.57080 0.00000 0.00000" xyz="0.00000 -0.12479 0.00000"/>
    <parent link="Sphere_link"/>
    <child link="Cone_link"/>
  </joint>
  <joint name="Cone_w2_link_joint" type="fixed">
    <origin rpy="1.57080 0.00000 0.00000" xyz="-0.00000 -0.12479 -0.00000"/>
    <parent link="Sphere_w2_link"/>
    <child link="Cone_w2_link"/>
  </joint>
  <joint name="Cone_w3_link_joint" type="fixed">
    <origin rpy="1.57080 -0.00000 -0.00000" xyz="-0.00000 -0.12479 0.00000"/>
    <parent link="Sphere_w3_link"/>
    <child link="Cone_w3_link"/>
  </joint>
  <joint name="Cone_w4_link_joint" type="fixed">
    <origin rpy="1.57080 -0.00000 -0.00000" xyz="0.00000 -0.12479 -0.00000"/>
    <parent link="Sphere_w4_link"/>
    <child link="Cone_w4_link"/>
  </joint>
  <joint name="Cylinder_link_joint" type="fixed">
    <origin rpy="-0.26180 0.00000 0.00000" xyz="-1.25000 -0.65807 -0.39906"/>
    <parent link="chasis_link"/>
    <child link="Cylinder_link"/>
  </joint>
  <joint name="Cylinder_w2_link_joint" type="fixed">
    <origin rpy="-0.26180 0.00000 0.00000" xyz="1.25000 -0.65807 -0.39860"/>
    <parent link="chasis_link"/>
    <child link="Cylinder_w2_link"/>
  </joint>
  <joint name="Cylinder_w3_link_joint" type="fixed">
    <origin rpy="-0.26180 -0.00000 -3.14159" xyz="-1.25000 0.47479 -0.40695"/>
    <parent link="chasis_link"/>
    <child link="Cylinder_w3_link"/>
  </joint>
  <joint name="Cylinder_w4_link_joint" type="fixed">
    <origin rpy="-0.26180 -0.00000 -3.14159" xyz="1.25000 0.47479 -0.40719"/>
    <parent link="chasis_link"/>
    <child link="Cylinder_w4_link"/>
  </joint>
  <joint name="Sphere_link_joint" type="fixed">
    <origin rpy="0.26180 0.00000 0.00000" xyz="0.00000 -0.01047 -0.41352"/>
    <parent link="Cylinder_link"/>
    <child link="Sphere_link"/>
  </joint>
  <joint name="Sphere_w2_link_joint" type="fixed">
    <origin rpy="0.26180 0.00000 0.00000" xyz="0.00000 -0.01047 -0.41352"/>
    <parent link="Cylinder_w2_link"/>
    <child link="Sphere_w2_link"/>
  </joint>
  <joint name="Sphere_w3_link_joint" type="fixed">
    <origin rpy="0.26180 0.00000 0.00000" xyz="-0.00000 -0.01267 -0.40736"/>
    <parent link="Cylinder_w3_link"/>
    <child link="Sphere_w3_link"/>
  </joint>
  <joint name="Sphere_w4_link_joint" type="fixed">
    <origin rpy="0.26180 0.00000 0.00000" xyz="-0.00000 -0.01267 -0.40736"/>
    <parent link="Cylinder_w4_link"/>
    <child link="Sphere_w4_link"/>
  </joint>
  <joint name="wheel_link_joint" type="continuous">
    <limit lower="0" upper="0" effort="0.00000" velocity="0.00000"/>
    <origin rpy="0.00000 0.00000 0.00000" xyz="0.00000 0.00000 0.10000"/>
    <parent link="Cone_link"/>
    <child link="wheel_link"/>
    <axis xyz="0.00000 0.00000 1.00000"/>
  </joint>
  <joint name="wheel_w2_link_joint" type="continuous">
    <limit lower="0" upper="0" effort="0.00000" velocity="0.00000"/>
    <origin rpy="0.00000 0.00000 0.00000" xyz="0.00000 0.00000 0.10000"/>
    <parent link="Cone_w2_link"/>
    <child link="wheel_w2_link"/>
    <axis xyz="0.00000 0.00000 1.00000"/>
  </joint>
  <joint name="wheel_w3_link_joint" type="continuous">
    <limit lower="0" upper="0" effort="0.00000" velocity="0.00000"/>
    <origin rpy="-0.00000 0.00000 -0.00000" xyz="-0.00000 -0.00000 0.10000"/>
    <parent link="Cone_w3_link"/>
    <child link="wheel_w3_link"/>
    <axis xyz="0.00000 0.00000 1.00000"/>
  </joint>
  <joint name="wheel_w4_link_joint" type="continuous">
    <limit lower="0" upper="0" effort="0.00000" velocity="0.00000"/>
    <origin rpy="-0.00000 0.00000 -0.00000" xyz="0.00000 -0.00000 0.10000"/>
    <parent link="Cone_w4_link"/>
    <child link="wheel_w4_link"/>
    <axis xyz="0.00000 0.00000 1.00000"/>
  </joint>
  <link name="Cone_link">
    <collision name="Cone_collision">
      <origin rpy="0.00000 0.00000 0.00000" xyz="0.00000 0.00000 0.00000"/>
      <geometry>
        <mesh filename="../meshes/dae/Cone.001.dae" scale="0.10000 0.10000 0.10000"/>
      </geometry>
    </collision>
    <inertial>
      <inertia ixx="0.00148" ixy="0.00000" ixz="-0.00000" iyy="0.00089" iyz="-0.00000" izz="0.00148"/>
      <origin rpy="0.00000 0.00000 0.00000" xyz="0.00000 -0.00000 -0.05000"/>
      <mass value="0.30000"/>
    </inertial>
    <visual name="Cone">
      <origin rpy="0.00000 0.00000 0.00000" xyz="0.00000 -0.00000 0.00000"/>
      <geometry>
        <mesh filename="../meshes/dae/Cone.001.dae" scale="0.10000 0.10000 0.10000"/>
      </geometry>
    </visual>
  </link>
  <link name="Cone_w2_link">
    <collision name="Cone_w2_collision">
      <origin rpy="0.00000 0.00000 0.00000" xyz="0.00000 -0.00000 -0.00000"/>
      <geometry>
        <mesh filename="../meshes/dae/Cone.002.dae" scale="0.10000 0.10000 0.10000"/>
      </geometry>
    </collision>
    <inertial>
      <inertia ixx="0.00148" ixy="0.00000" ixz="-0.00000" iyy="0.00089" iyz="-0.00000" izz="0.00148"/>
      <origin rpy="0.00000 0.00000 0.00000" xyz="0.00000 -0.00000 -0.05000"/>
      <mass value="0.30000"/>
    </inertial>
    <visual name="Cone_w2">
      <origin rpy="0.00000 0.00000 0.00000" xyz="0.00000 -0.00000 -0.00000"/>
      <geometry>
        <mesh filename="../meshes/dae/Cone.002.dae" scale="0.10000 0.10000 0.10000"/>
      </geometry>
    </visual>
  </link>
  <link name="Cone_w3_link">
    <collision name="Cone_w3_collision">
      <origin rpy="0.00000 0.00000 -3.14159" xyz="0.00000 -0.00000 0.00000"/>
      <geometry>
        <mesh filename="../meshes/dae/Cone.003.dae" scale="0.10000 0.10000 0.10000"/>
      </geometry>
    </collision>
    <inertial>
      <inertia ixx="0.00148" ixy="0.00000" ixz="0.00000" iyy="0.00089" iyz="0.00000" izz="0.00148"/>
      <origin rpy="0.00000 0.00000 0.00000" xyz="0.00000 -0.00000 -0.05000"/>
      <mass value="0.30000"/>
    </inertial>
    <visual name="Cone_w3">
      <origin rpy="-0.00000 0.00000 -0.00000" xyz="0.00000 -0.00000 0.00000"/>
      <geometry>
        <mesh filename="../meshes/dae/Cone.003.dae" scale="0.10000 0.10000 0.10000"/>
      </geometry>
    </visual>
  </link>
  <link name="Cone_w4_link">
    <collision name="Cone_w4_collision">
      <origin rpy="0.00000 0.00000 -3.14159" xyz="0.00000 -0.00000 0.00000"/>
      <geometry>
        <mesh filename="../meshes/dae/Cone.007.dae" scale="0.10000 0.10000 0.10000"/>
      </geometry>
    </collision>
    <inertial>
      <inertia ixx="0.00148" ixy="0.00000" ixz="0.00000" iyy="0.00089" iyz="0.00000" izz="0.00148"/>
      <origin rpy="0.00000 0.00000 0.00000" xyz="0.00000 -0.00000 -0.05000"/>
      <mass value="0.30000"/>
    </inertial>
    <visual name="Cone_w4">
      <origin rpy="-0.00000 0.00000 -0.00000" xyz="0.00000 -0.00000 0.00000"/>
      <geometry>
        <mesh filename="../meshes/dae/Cone.007.dae" scale="0.10000 0.10000 0.10000"/>
      </geometry>
    </visual>
  </link>
  <link name="Cylinder_link">
    <collision name="Cylinder_collision">
      <origin rpy="0.00000 0.00000 0.00000" xyz="0.00000 0.00000 0.00000"/>
      <geometry>
        <cylinder radius="0.05000" length="0.75000"/>
      </geometry>
    </collision>
    <inertial>
      <inertia ixx="0.03800" ixy="0.00000" ixz="0.00000" iyy="0.03552" iyz="-0.00925" izz="0.00348"/>
      <origin rpy="0.00000 0.00000 0.00000" xyz="0.00000 0.00000 -0.00000"/>
      <mass value="0.80000"/>
    </inertial>
    <visual name="Cylinder">
      <origin rpy="0.00000 0.00000 0.00000" xyz="0.00000 0.00000 -0.00000"/>
      <geometry>
        <cylinder radius="0.05000" length="0.75000"/>
      </geometry>
    </visual>
  </link>
  <link name="Cylinder_w2_link">
    <collision name="Cylinder_w2_collision">
      <origin rpy="0.00000 0.00000 0.00000" xyz="0.00000 0.00000 -0.00000"/>
      <geometry>
        <cylinder radius="0.05000" length="0.75000"/>
      </geometry>
    </collision>
    <inertial>
      <inertia ixx="0.03800" ixy="0.00000" ixz="0.00000" iyy="0.03552" iyz="-0.00925" izz="0.00348"/>
      <origin rpy="0.00000 0.00000 0.00000" xyz="0.00000 0.00000 -0.00000"/>
      <mass value="0.80000"/>
    </inertial>
    <visual name="Cylinder_w2">
      <origin rpy="0.00000 0.00000 0.00000" xyz="0.00000 0.00000 -0.00000"/>
      <geometry>
        <cylinder radius="0.05000" length="0.75000"/>
      </geometry>
    </visual>
  </link>
  <link name="Cylinder_w3_link">
    <collision name="Cylinder_w3_collision">
      <origin rpy="-0.00000 -0.00000 3.14159" xyz="0.00000 -0.00000 0.00000"/>
      <geometry>
        <cylinder radius="0.05000" length="0.75000"/>
      </geometry>
    </collision>
    <inertial>
      <inertia ixx="0.03800" ixy="0.00000" ixz="-0.00000" iyy="0.03552" iyz="0.00925" izz="0.00348"/>
      <origin rpy="0.00000 0.00000 0.00000" xyz="0.00000 -0.00000 0.00000"/>
      <mass value="0.80000"/>
    </inertial>
    <visual name="Cylinder_w3">
      <origin rpy="0.00000 -0.00000 0.00000" xyz="0.00000 -0.00000 0.00000"/>
      <geometry>
        <cylinder radius="0.05000" length="0.75000"/>
      </geometry>
    </visual>
  </link>
  <link name="Cylinder_w4_link">
    <collision name="Cylinder_w4_collision">
      <origin rpy="-0.00000 -0.00000 3.14159" xyz="-0.00000 0.00000 0.00000"/>
      <geometry>
        <cylinder radius="0.05000" length="0.75000"/>
      </geometry>
    </collision>
    <inertial>
      <inertia ixx="0.03800" ixy="0.00000" ixz="-0.00000" iyy="0.03552" iyz="0.00925" izz="0.00348"/>
      <origin rpy="0.00000 0.00000 0.00000" xyz="-0.00000 0.00000 0.00000"/>
      <mass value="0.80000"/>
    </inertial>
    <visual name="Cylinder_w4">
      <origin rpy="0.00000 -0.00000 0.00000" xyz="-0.00000 -0.00000 0.00000"/>
      <geometry>
        <cylinder radius="0.05000" length="0.75000"/>
      </geometry>
    </visual>
  </link>
  <link name="Sphere_link">
    <collision name="Sphere_collision">
      <origin rpy="0.00000 0.00000 0.00000" xyz="0.00000 0.00000 0.00000"/>
      <geometry>
        <sphere radius="0.10000"/>
      </geometry>
    </collision>
    <inertial>
      <inertia ixx="0.00120" ixy="0.00000" ixz="0.00000" iyy="0.00120" iyz="0.00000" izz="0.00120"/>
      <origin rpy="0.00000 0.00000 0.00000" xyz="0.00000 0.00000 0.00000"/>
      <mass value="0.30000"/>
    </inertial>
    <visual name="Sphere">
      <origin rpy="0.00000 0.00000 0.00000" xyz="0.00000 0.00000 0.00000"/>
      <geometry>
        <sphere radius="0.10000"/>
      </geometry>
    </visual>
  </link>
  <link name="Sphere_w2_link">
    <collision name="Sphere_w2_collision">
      <origin rpy="0.00000 0.00000 0.00000" xyz="-0.00000 -0.00000 -0.00000"/>
      <geometry>
        <sphere radius="0.10000"/>
      </geometry>
    </collision>
    <inertial>
      <inertia ixx="0.00120" ixy="0.00000" ixz="0.00000" iyy="0.00120" iyz="0.00000" izz="0.00120"/>
      <origin rpy="0.00000 0.00000 0.00000" xyz="-0.00000 -0.00000 0.00000"/>
      <mass value="0.30000"/>
    </inertial>
    <visual name="Sphere_w2">
      <origin rpy="0.00000 0.00000 0.00000" xyz="-0.00000 -0.00000 0.00000"/>
      <geometry>
        <sphere radius="0.10000"/>
      </geometry>
    </visual>
  </link>
  <link name="Sphere_w3_link">
    <collision name="Sphere_w3_collision">
      <origin rpy="0.00000 0.00000 3.14159" xyz="0.00000 -0.00000 -0.00000"/>
      <geometry>
        <sphere radius="0.10000"/>
      </geometry>
    </collision>
    <inertial>
      <inertia ixx="0.00120" ixy="0.00000" ixz="0.00000" iyy="0.00120" iyz="-0.00000" izz="0.00120"/>
      <origin rpy="0.00000 0.00000 0.00000" xyz="0.00000 -0.00000 -0.00000"/>
      <mass value="0.30000"/>
    </inertial>
    <visual name="Sphere_w3">
      <origin rpy="0.00000 0.00000 0.00000" xyz="0.00000 -0.00000 -0.00000"/>
      <geometry>
        <sphere radius="0.10000"/>
      </geometry>
    </visual>
  </link>
  <link name="Sphere_w4_link">
    <collision name="Sphere_w4_collision">
      <origin rpy="0.00000 0.00000 3.14159" xyz="0.00000 -0.00000 -0.00000"/>
      <geometry>
        <sphere radius="0.10000"/>
      </geometry>
    </collision>
    <inertial>
      <inertia ixx="0.00120" ixy="0.00000" ixz="0.00000" iyy="0.00120" iyz="-0.00000" izz="0.00120"/>
      <origin rpy="0.00000 0.00000 0.00000" xyz="0.00000 -0.00000 -0.00000"/>
      <mass value="0.30000"/>
    </inertial>
    <visual name="Sphere_w4">
      <origin rpy="0.00000 0.00000 0.00000" xyz="0.00000 -0.00000 -0.00000"/>
      <geometry>
        <sphere radius="0.10000"/>
      </geometry>
    </visual>
  </link>
  <link name="chasis_link">
    <collision name="chasis_collision">
      <origin rpy="0.00000 0.00000 0.00000" xyz="0.00000 0.00000 -0.00632"/>
      <geometry>
        <mesh filename="../meshes/dae/Cube.004.dae" scale="1.50000 1.00000 0.05000"/>
      </geometry>
    </collision>
    <inertial>
      <inertia ixx="1.67083" ixy="0.00000" ixz="0.00000" iyy="3.75417" iyz="0.00000" izz="5.41667"/>
      <origin rpy="0.00000 0.00000 0.00000" xyz="0.00000 0.00000 0.01760"/>
      <mass value="5.00000"/>
    </inertial>
    <visual name="chasis">
      <origin rpy="0.00000 0.00000 0.00000" xyz="0.00000 0.00000 -0.00632"/>
      <geometry>
        <box size="3.00000 2.00000 0.10000"/>
      </geometry>
    </visual>
  </link>
  <link name="wheel_link">
    <collision name="wheel_collision">
      <origin rpy="0.00000 0.00000 0.00000" xyz="0.00000 0.00000 0.00000"/>
      <geometry>
        <mesh filename="../meshes/dae/Torus.dae" scale="0.20000 0.20000 0.50000"/>
      </geometry>
    </collision>
    <inertial>
      <inertia ixx="0.01774" ixy="0.00000" ixz="0.00000" iyy="0.02932" iyz="0.00000" izz="0.01774"/>
      <origin rpy="0.00000 0.00000 0.00000" xyz="0.00000 -0.00000 -0.00000"/>
      <mass value="1.00000"/>
    </inertial>
    <visual name="wheel">
      <origin rpy="0.00000 0.00000 0.00000" xyz="0.00000 0.00000 0.00000"/>
      <geometry>
        <mesh filename="../meshes/dae/Torus.dae" scale="0.20000 0.20000 0.50000"/>
      </geometry>
    </visual>
  </link>
  <link name="wheel_w2_link">
    <collision name="wheel_w2_collision">
      <origin rpy="0.00000 0.00000 0.00000" xyz="-0.00000 -0.00000 0.00000"/>
      <geometry>
        <mesh filename="../meshes/dae/Torus.001.dae" scale="0.20000 0.20000 0.50000"/>
      </geometry>
    </collision>
    <inertial>
      <inertia ixx="0.01774" ixy="0.00000" ixz="0.00000" iyy="0.02932" iyz="0.00000" izz="0.01774"/>
      <origin rpy="0.00000 0.00000 0.00000" xyz="-0.00000 -0.00000 0.00000"/>
      <mass value="1.00000"/>
    </inertial>
    <visual name="wheel_w2">
      <origin rpy="0.00000 0.00000 0.00000" xyz="-0.00000 -0.00000 0.00000"/>
      <geometry>
        <mesh filename="../meshes/dae/Torus.001.dae" scale="0.20000 0.20000 0.50000"/>
      </geometry>
    </visual>
  </link>
  <link name="wheel_w3_link">
    <collision name="wheel_w3_collision">
      <origin rpy="-3.14159 0.00000 -3.14159" xyz="0.00000 -0.00000 0.00000"/>
      <geometry>
        <mesh filename="../meshes/dae/Torus.002.dae" scale="0.20000 0.20000 0.50000"/>
      </geometry>
    </collision>
    <inertial>
      <inertia ixx="0.01774" ixy="-0.00000" ixz="-0.00000" iyy="0.02932" iyz="-0.00000" izz="0.01774"/>
      <origin rpy="0.00000 0.00000 0.00000" xyz="0.00000 -0.00000 0.00000"/>
      <mass value="1.00000"/>
    </inertial>
    <visual name="wheel_w3">
      <origin rpy="-0.00000 -0.00000 0.00000" xyz="0.00000 -0.00000 0.00000"/>
      <geometry>
        <mesh filename="../meshes/dae/Torus.002.dae" scale="0.20000 0.20000 0.50000"/>
      </geometry>
    </visual>
  </link>
  <link name="wheel_w4_link">
    <collision name="wheel_w4_collision">
      <origin rpy="-3.14159 0.00000 -3.14159" xyz="-0.00000 -0.00000 0.00000"/>
      <geometry>
        <mesh filename="../meshes/dae/Torus.006.dae" scale="0.20000 0.20000 0.50000"/>
      </geometry>
    </collision>
    <inertial>
      <inertia ixx="0.01774" ixy="-0.00000" ixz="-0.00000" iyy="0.02932" iyz="-0.00000" izz="0.01774"/>
      <origin rpy="0.00000 0.00000 0.00000" xyz="0.00000 -0.00000 0.00000"/>
      <mass value="1.00000"/>
    </inertial>
    <visual name="wheel_w4">
      <origin rpy="-0.00000 -0.00000 0.00000" xyz="0.00000 -0.00000 0.00000"/>
      <geometry>
        <mesh filename="../meshes/dae/Torus.006.dae" scale="0.20000 0.20000 0.50000"/>
      </geometry>
    </visual>
  </link>
</robot>