<?xml version="1.0"?>
<robot name="barrier">


    <!-- El siguiente link suelo, lo he usado para modelar el urdf con la 
    extension de urdf visualizer de vscode. Lo dejo comentado porque de lo
    contrario, daría error (no pertenece a un joint habiendo 3 links y 2 joints)
    pero no lo elimino porque podría ser útil de cara a modificar la rampa
    en posibles escenarios futuros -->
    <!-- <link name="suelo">

        <inertial>
            <origin xyz="0 0 -0.5"/>
            <mass value="1.0"/>
            <inertia ixx="1.0" ixy="0.0" ixz="0.0"
                iyy="1.0" iyz="0.0" izz="1.0"/>
        </inertial>

        <visual>
            <origin xyz="0 0 -0.5"/>
            <geometry>
                <box size="2 2 0"/>
            </geometry>
            <material name="blue">
                <color rgba="0 0 0.8 1"/>
            </material>
        </visual>

        <collision>
            <origin xyz="0 0 -0.5"/>
            <geometry>
                <box size="2 5 0"/>
            </geometry>
        </collision>

    </link> -->

    <link name="cylinder_link">

        <inertial>
            <origin xyz="0 0 0"/>
            <mass value="100.0"/>
            <inertia ixx="0.00001" ixy="0.0" ixz="0.0"
                iyy="0.00001" iyz="0.0" izz="0.00001"/>
        </inertial>

        <visual>
            <origin xyz="0 0 0"/>
            <geometry>
                <cylinder radius="0.1" length="1.0"/>
            </geometry>

            <material name="red">
                <color rgba="1 0 0 1"/>
            </material>
        </visual>

        <collision>
            <origin xyz="0 0 0"/>
            <geometry>
                <cylinder radius="0.1" length="1.0"/>
            </geometry>
        </collision>

    </link>


    <link name="horizontal_link">

        <inertial>
            <origin xyz="0 0 0"/>
            <mass value="5.0"/>
            <inertia ixx="1.3" ixy="0.0" ixz="0.0"
                iyy="3" iyz="0.0" izz="1.7"/>
        </inertial>

        <visual>
            <origin xyz="0 0 0"/>
            <geometry>
                <box size="0.2 2 0.2"/>
            </geometry>

            <material name="red">
                <color rgba="1 0 0 1"/>
            </material>
        </visual>

        <collision>
            <origin xyz="0 0 0"/>
            <geometry>
                <box size="0.2 2 0.2"/>
            </geometry>
        </collision>

    </link>

    <joint name="clylinder_to_horizontal" type="revolute">
        <parent link="cylinder_link"/>
        <child link="horizontal_link"/>
        <dynamics damping="0.1" friction="0.0001"/>
        <limit lower="-1.57" upper="1.57"/>

        <origin xyz="0 -0.5 -0.15"/>
        <axis xyz="0 1 0"/>
        
    </joint>

</robot>
